Workbook

Sheet Aeronaves
A1: AERONAVES | Especificaciones disponibles
A3: 243 filas originales · Consulta: 13 septiembre 2026 · Consulte variantes y fuentes antes de combinar datos
A4: BADA: sin acceso a datos licenciados. Celdas vacías = dato no verificado; no equivalen a cero.
A6: Código ICAO del CSV | B6: Modelo de referencia MTOW | C6: Superficie alar pública (m²) | D6: MTOW de referencia (kg) | E6: Longitud fuselaje OpenAP (m) | F6: Longitud total / publicada (m) | G6: N.º motores principales | H6: Superficie alar BADA (m²) | I6: Cobertura
A7: A320 | B7: Airbus A320 | C7: 124 | D7: =ROUND(Fuentes!I7*0.45359237,0) -> 78000 | E7: 37.57 | F7: =ROUND(Fuentes!J7*0.3048,2) -> 37.58 | G7: 2 | I7: Con datos
A8: E170 | B8: Embraer 170 | C8: 72.72 | D8: =ROUND(Fuentes!I8*0.45359237,0) -> 38600 | E8: 29.9 | F8: =ROUND(Fuentes!J8*0.3048,2) -> 29.9 | G8: 2 | I8: Con datos
A9: A346 | B9: Airbus A340-600 | D9: =ROUND(Fuentes!I9*0.45359237,0) -> 380000 | F9: =ROUND(Fuentes!J9*0.3048,2) -> 75.35 | G9: 4 | I9: Con datos
A10: B748 | B10: Boeing 747-8 | C10: 554 | D10: =ROUND(Fuentes!I10*0.45359237,0) -> 447696 | E10: 76.3 | F10: =ROUND(Fuentes!J10*0.3048,2) -> 76.26 | G10: 4 | I10: Con datos
A11: E190 | B11: Embraer 190 | C11: 92.5 | D11: =ROUND(Fuentes!I11*0.45359237,0) -> 50300 | E11: 36.24 | F11: =ROUND(Fuentes!J11*0.3048,2) -> 36.24 | G11: 2 | I11: Con datos
A12: A319 | B12: Airbus A319 | C12: 124 | D12: =ROUND(Fuentes!I12*0.45359237,0) -> 76500 | E12: 33.84 | F12: =ROUND(Fuentes!J12*0.3048,2) -> 33.83 | G12: 2 | I12: Con datos
A13: A339 | B13: Airbus A330-900 | D13: =ROUND(Fuentes!I13*0.45359237,0) -> 251018 | F13: =ROUND(Fuentes!J13*0.3048,2) -> 63.67 | G13: 2 | I13: Con datos
A14: CRJX | B14: Bombardier CRJ1000 | D14: 40824 | F14: 39.13 | G14: 2 | I14: Con datos
A15: A20N | B15: Airbus A320 Neo | C15: 124 | D15: =ROUND(Fuentes!I15*0.45359237,0) -> 79000 | E15: 37.57 | F15: =ROUND(Fuentes!J15*0.3048,2) -> 37.58 | G15: 2 | I15: Con datos
A16: CRJ9 | B16: canadair CRJ-900 | C16: 71.07 | D16: =ROUND(Fuentes!I16*0.45359237,0) -> 36514 | E16: 33.5 | F16: =ROUND(Fuentes!J16*0.3048,2) -> 36.21 | G16: 2 | I16: Con datos
A17: A332 | B17: Airbus A330-200 | C17: 361.6 | D17: =ROUND(Fuentes!I17*0.45359237,0) -> 242000 | E17: 58.82 | F17: =ROUND(Fuentes!J17*0.3048,2) -> 59.01 | G17: 2 | I17: Con datos
A18: E75L | B18: Embraer 175 long wing | C18: 72.72 | D18: =ROUND(Fuentes!I18*0.45359237,0) -> 38790 | E18: 29.9 | F18: =ROUND(Fuentes!J18*0.3048,2) -> 32.31 | G18: 2 | I18: Con datos
A19: B77L | B19: Boeing 777-200LRF/LR | D19: =ROUND(Fuentes!I19*0.45359237,0) -> 347500 | F19: =ROUND(Fuentes!J19*0.3048,2) -> 63.73 | G19: 2 | I19: Con datos
A20: A333 | B20: Airbus A330-300 | C20: 361.6 | D20: =ROUND(Fuentes!I20*0.45359237,0) -> 242000 | E20: 63.67 | F20: =ROUND(Fuentes!J20*0.3048,2) -> 63.7 | G20: 2 | I20: Con datos
A21: A21N | B21: Airbus A321 Neo | C21: 128 | D21: =ROUND(Fuentes!I21*0.45359237,0) -> 95000 | E21: 44.51 | F21: =ROUND(Fuentes!J21*0.3048,2) -> 44.5 | G21: 2 | I21: Con datos
A22: A321 | B22: Airbus A321 | C22: 128 | D22: =ROUND(Fuentes!I22*0.45359237,0) -> 91000 | E22: 44.51 | F22: =ROUND(Fuentes!J22*0.3048,2) -> 44.5 | G22: 2 | I22: Con datos
A23: B77W | B23: Boeing 777-300ER | C23: 436.8 | D23: =ROUND(Fuentes!I23*0.45359237,0) -> 351534 | E23: 73.86 | F23: =ROUND(Fuentes!J23*0.3048,2) -> 73.85 | G23: 2 | I23: Con datos
A24: BCS3 | B24: Airbus A220-300 | D24: =ROUND(Fuentes!I24*0.45359237,0) -> 70900 | F24: =ROUND(Fuentes!J24*0.3048,2) -> 38.71 | G24: 2 | I24: Con datos
A25: B738 | B25: Boeing 737-800 | C25: 124.6 | D25: =ROUND(Fuentes!I25*0.45359237,0) -> 79016 | E25: 39.47 | F25: =ROUND(Fuentes!J25*0.3048,2) -> 39.47 | G25: 2 | I25: Con datos
A26: E195 | B26: Embraer 195 | C26: 92.5 | D26: =ROUND(Fuentes!I26*0.45359237,0) -> 52290 | E26: 38.65 | F26: =ROUND(Fuentes!J26*0.3048,2) -> 38.65 | G26: 2 | I26: Con datos
A27: B789 | B27: Boeing 787-9 Dreamliner | C27: 377 | D27: =ROUND(Fuentes!I27*0.45359237,0) -> 254012 | E27: 62.81 | F27: =ROUND(Fuentes!J27*0.3048,2) -> 62.82 | G27: 2 | I27: Con datos
A28: A343 | B28: Airbus A340-300 | C28: 363.1 | D28: =ROUND(Fuentes!I28*0.45359237,0) -> 276500 | E28: 63.69 | F28: =ROUND(Fuentes!J28*0.3048,2) -> 63.7 | G28: 4 | I28: Con datos
A29: A306 | B29: Airbus A300 B4-600 | D29: =ROUND(Fuentes!I29*0.45359237,0) -> 164999 | F29: =ROUND(Fuentes!J29*0.3048,2) -> 54.07 | G29: 2 | I29: Con datos
A30: B752 | B30: Boeing 757-200 | C30: 182.3 | D30: =ROUND(Fuentes!I30*0.45359237,0) -> 115893 | E30: 47.3 | F30: =ROUND(Fuentes!J30*0.3048,2) -> 47.34 | G30: 2 | I30: Con datos
A31: A359 | B31: Airbus 350-900 | C31: 442 | D31: =ROUND(Fuentes!I31*0.45359237,0) -> 280000 | E31: 66.8 | F31: =ROUND(Fuentes!J31*0.3048,2) -> 66.61 | G31: 2 | I31: Con datos
A32: B763 | B32: Boeing 767-300 | C32: 283.3 | D32: =ROUND(Fuentes!I32*0.45359237,0) -> 186880 | E32: 54.94 | F32: =ROUND(Fuentes!J32*0.3048,2) -> 54.96 | G32: 2 | I32: Con datos
A33: E55P | B33: Embraer Phenom 300 | D33: =ROUND(Fuentes!I33*0.45359237,0) -> 8150 | F33: =ROUND(Fuentes!J33*0.3048,2) -> 15.64 | G33: 2 | I33: Con datos
A34: CL35 | B34: Bombardier Challenger 350 | D34: =ROUND(Fuentes!I34*0.45359237,0) -> 18416 | F34: =ROUND(Fuentes!J34*0.3048,2) -> 20.91 | G34: 2 | I34: Con datos
A35: C25B | B35: Cessna Citation CJ3 | C35: 27.32 | D35: =ROUND(Fuentes!I35*0.45359237,0) -> 6291 | F35: =ROUND(Fuentes!J35*0.3048,2) -> 15.61 | G35: 2 | I35: Con datos
A36: B78X | B36: Boeing 787-10 Dreamliner | D36: =ROUND(Fuentes!I36*0.45359237,0) -> 254012 | F36: =ROUND(Fuentes!J36*0.3048,2) -> 68.31 | G36: 2 | I36: Con datos
A37: B744 | B37: Boeing 747-400 | C37: 525.6 | D37: =ROUND(Fuentes!I37*0.45359237,0) -> 412769 | E37: 70.66 | F37: =ROUND(Fuentes!J37*0.3048,2) -> 70.68 | G37: 4 | I37: Con datos
A38: B38M | B38: Boeing 737 MAX 8 | C38: 124.6 | D38: =ROUND(Fuentes!I38*0.45359237,0) -> 82191 | E38: 39.47 | F38: =ROUND(Fuentes!J38*0.3048,2) -> 39.53 | G38: 2 | I38: Con datos
A39: AT72 | B39: ATR 72-200, opción MTOW | C39: 61 | D39: 22000 | F39: 27.166 | G39: 2 | I39: Con datos
A40: B788 | B40: Boeing 787-8 BBJ/Dreamliner | C40: 377 | D40: =ROUND(Fuentes!I40*0.45359237,0) -> 227930 | E40: 56.72 | F40: =ROUND(Fuentes!J40*0.3048,2) -> 56.72 | G40: 2 | I40: Con datos
A41: B772 | B41: Boeing 777-200 | C41: 427.8 | D41: =ROUND(Fuentes!I41*0.45359237,0) -> 297557 | E41: 63.73 | F41: =ROUND(Fuentes!J41*0.3048,2) -> 63.73 | G41: 2 | I41: Con datos
I42: Pendiente
...

Sheet Fuentes
A1: TRAZABILIDAD | Fuentes por campo
A3: Una fila por registro original · Los enlaces identifican la fuente exacta utilizada en cada campo
A6: Código del CSV | B6: Variante superficie alar | C6: Origen superficie alar | D6: URL superficie alar | E6: URL MTOW | F6: URL longitud publicada | G6: URL motores | H6: URL fuselaje OpenAP | I6: FAA MTOW original (lb) | J6: FAA longitud original (ft) | K6: Definición longitud | L6: Observaciones
A7: A320 | B7: Airbus A320 | C7: OpenAP: parámetro wing.area (no BADA) | D7: https://github.com/junzis/openap/blob/master/openap/data/aircraft/a320.yml | E7: https://www.faa.gov/airports/engineering/aircraft_char_database/aircraft_data | F7: https://www.faa.gov/airports/engineering/aircraft_char_database/aircraft_data | G7: https://www.faa.gov/airports/engineering/aircraft_char_database/aircraft_data | H7: https://github.com/junzis/openap/blob/master/openap/data/aircraft/a320.yml | I7: 171961 | J7: 123.3 | K7: Longitud total (FAA) | L7: FAA ACD octubre 2024: configuración de referencia, no máximo entre todas las variantes. AAC validated by Flight Standardization Board (FSB) report.
A8: E170 | B8: Embraer E170 | C8: OpenAP: parámetro wing.area (no BADA) | D8: https://github.com/junzis/openap/blob/master/openap/data/aircraft/e170.yml | E8: https://www.faa.gov/airports/engineering/aircraft_char_database/aircraft_data | F8: https://www.faa.gov/airports/engineering/aircraft_char_database/aircraft_data | G8: https://www.faa.gov/airports/engineering/aircraft_char_database/aircraft_data | H8: https://github.com/junzis/openap/blob/master/openap/data/aircraft/e170.yml | I8: 85098 | J8: 98.1 | K8: Longitud total (FAA) | L8: FAA ACD octubre 2024: configuración de referencia, no máximo entre todas las variantes. AAC validated by Flight Standardization Board (FSB) report.
A9: A346 | C9: No disponible | E9: https://www.faa.gov/airports/engineering/aircraft_char_database/aircraft_data | F9: https://www.faa.gov/airports/engineering/aircraft_char_database/aircraft_data | G9: https://www.faa.gov/airports/engineering/aircraft_char_database/aircraft_data | I9: 837756 | J9: 247.2 | K9: Longitud total (FAA) | L9: FAA ACD octubre 2024: configuración de referencia, no máximo entre todas las variantes.
A10: B748 | B10: Boeing 747-8 | C10: OpenAP: parámetro wing.area (no BADA) | D10: https://github.com/junzis/openap/blob/master/openap/data/aircraft/b748.yml | E10: https://www.faa.gov/airports/engineering/aircraft_char_database/aircraft_data | F10: https://www.faa.gov/airports/engineering/aircraft_char_database/aircraft_data | G10: https://www.faa.gov/airports/engineering/aircraft_char_database/aircraft_data | H10: https://github.com/junzis/openap/blob/master/openap/data/aircraft/b748.yml | I10: 987000 | J10: 250.2 | K10: Longitud total (FAA) | L10: FAA ACD octubre 2024: configuración de referencia, no máximo entre todas las variantes. AAC validated by Flight Standardization Board (FSB) report.
A11: E190 | B11: Embraer E190 (LR) | C11: OpenAP: parámetro wing.area (no BADA) | D11: https://github.com/junzis/openap/blob/master/openap/data/aircraft/e190.yml | E11: https://www.faa.gov/airports/engineering/aircraft_char_database/aircraft_data | F11: https://www.faa.gov/airports/engineering/aircraft_char_database/aircraft_data | G11: https://www.faa.gov/airports/engineering/aircraft_char_database/aircraft_data | H11: https://github.com/junzis/openap/blob/master/openap/data/aircraft/e190.yml | I11: 110892 | J11: 118.9 | K11: Longitud total (FAA) | L11: FAA ACD octubre 2024: configuración de referencia, no máximo entre todas las variantes. AAC validated by Flight Standardization Board (FSB) report.
A12: A319 | B12: Airbus A319 | C12: OpenAP: parámetro wing.area (no BADA) | D12: https://github.com/junzis/openap/blob/master/openap/data/aircraft/a319.yml | E12: https://www.faa.gov/airports/engineering/aircraft_char_database/aircraft_data | F12: https://www.faa.gov/airports/engineering/aircraft_char_database/aircraft_data | G12: https://www.faa.gov/airports/engineering/aircraft_char_database/aircraft_data | H12: https://github.com/junzis/openap/blob/master/openap/data/aircraft/a319.yml | I12: 168653 | J12: 111 | K12: Longitud total (FAA) | L12: FAA ACD octubre 2024: configuración de referencia, no máximo entre todas las variantes. AAC validated by Flight Standardization Board (FSB) report.
A13: A339 | C13: No disponible | E13: https://www.faa.gov/airports/engineering/aircraft_char_database/aircraft_data | F13: https://www.faa.gov/airports/engineering/aircraft_char_database/aircraft_data | G13: https://www.faa.gov/airports/engineering/aircraft_char_database/aircraft_data | I13: 553400 | J13: 208.9 | K13: Longitud total (FAA) | L13: FAA ACD octubre 2024: configuración de referencia, no máximo entre todas las variantes. AAC validated by Flight Standardization Board (FSB) report.
A14: CRJX | C14: No disponible | E14: https://contentzone.eurocontrol.int/aircraftperformance/details.aspx?ICAO=CRJX | F14: https://contentzone.eurocontrol.int/aircraftperformance/details.aspx?ICAO=CRJX | G14: https://contentzone.eurocontrol.int/aircraftperformance/details.aspx?ICAO=CRJX | K14: Longitud publicada; definición no desglosada | L14: EUROCONTROL Aircraft Performance Database pública; no es la base BADA licenciada.
A15: A20N | B15: Airbus A320neo | C15: OpenAP: parámetro wing.area (no BADA) | D15: https://github.com/junzis/openap/blob/master/openap/data/aircraft/a20n.yml | E15: https://www.faa.gov/airports/engineering/aircraft_char_database/aircraft_data | F15: https://www.faa.gov/airports/engineering/aircraft_char_database/aircraft_data | G15: https://www.faa.gov/airports/engineering/aircraft_char_database/aircraft_data | H15: https://github.com/junzis/openap/blob/master/openap/data/aircraft/a20n.yml | I15: 174165 | J15: 123.3 | K15: Longitud total (FAA) | L15: FAA ACD octubre 2024: configuración de referencia, no máximo entre todas las variantes. AAC validated by Flight Standardization Board (FSB) report.
A16: CRJ9 | B16: BOMBARDIER CRJ9 | C16: OpenAP: parámetro wing.area (no BADA) | D16: https://github.com/junzis/openap/blob/master/openap/data/aircraft/crj9.yml | E16: https://www.faa.gov/airports/engineering/aircraft_char_database/aircraft_data | F16: https://www.faa.gov/airports/engineering/aircraft_char_database/aircraft_data | G16: https://www.faa.gov/airports/engineering/aircraft_char_database/aircraft_data | H16: https://github.com/junzis/openap/blob/master/openap/data/aircraft/crj9.yml | I16: 80500 | J16: 118.8 | K16: Longitud total (FAA) | L16: FAA ACD octubre 2024: configuración de referencia, no máximo entre todas las variantes. Long Range version has an increased MALW, such that CRJ9 approach Category falls into D. AAC validated by Flight Standardization Board (FSB) report.
A17: A332 | B17: Airbus A330-200 | C17: OpenAP: parámetro wing.area (no BADA) | D17: https://github.com/junzis/openap/blob/master/openap/data/aircraft/a332.yml | E17: https://www.faa.gov/airports/engineering/aircraft_char_database/aircraft_data | F17: https://www.faa.gov/airports/engineering/aircraft_char_database/aircraft_data | G17: https://www.faa.gov/airports/engineering/aircraft_char_database/aircraft_data | H17: https://github.com/junzis/openap/blob/master/openap/data/aircraft/a332.yml | I17: 533519 | J17: 193.6 | K17: Longitud total (FAA) | L17: FAA ACD octubre 2024: configuración de referencia, no máximo entre todas las variantes. AAC validated by Flight Standardization Board (FSB) report.
A18: E75L | B18: Embraer E175 (LR) | C18: OpenAP: parámetro wing.area (no BADA) | D18: https://github.com/junzis/openap/blob/master/openap/data/aircraft/e75l.yml | E18: https://www.faa.gov/airports/engineering/aircraft_char_database/aircraft_data | F18: https://www.faa.gov/airports/engineering/aircraft_char_database/aircraft_data | G18: https://www.faa.gov/airports/engineering/aircraft_char_database/aircraft_data | H18: https://github.com/junzis/openap/blob/master/openap/data/aircraft/e75l.yml | I18: 85517 | J18: 106 | K18: Longitud total (FAA) | L18: FAA ACD octubre 2024: configuración de referencia, no máximo entre todas las variantes. AAC validated by Flight Standardization Board (FSB) report.
A19: B77L | C19: No disponible | E19: https://www.faa.gov/airports/engineering/aircraft_char_database/aircraft_data | F19: https://www.faa.gov/airports/engineering/aircraft_char_database/aircraft_data | G19: https://www.faa.gov/airports/engineering/aircraft_char_database/aircraft_data | I19: 766106 | J19: 209.1 | K19: Longitud total (FAA) | L19: FAA ACD octubre 2024: configuración de referencia, no máximo entre todas las variantes. AAC validated by Flight Standardization Board (FSB) report.
A20: A333 | B20: Airbus A330-300 | C20: OpenAP: parámetro wing.area (no BADA) | D20: https://github.com/junzis/openap/blob/master/openap/data/aircraft/a333.yml | E20: https://www.faa.gov/airports/engineering/aircraft_char_database/aircraft_data | F20: https://www.faa.gov/airports/engineering/aircraft_char_database/aircraft_data | G20: https://www.faa.gov/airports/engineering/aircraft_char_database/aircraft_data | H20: https://github.com/junzis/openap/blob/master/openap/data/aircraft/a333.yml | I20: 533519 | J20: 209 | K20: Longitud total (FAA) | L20: FAA ACD octubre 2024: configuración de referencia, no máximo entre todas las variantes. AAC validated by Flight Standardization Board (FSB) report.
A21: A21N | B21: Airbus A321neo | C21: OpenAP: parámetro wing.area (no BADA) | D21: https://github.com/junzis/openap/blob/master/openap/data/aircraft/a21n.yml | E21: https://www.faa.gov/airports/engineering/aircraft_char_database/aircraft_data | F21: https://www.faa.gov/airports/engineering/aircraft_char_database/aircraft_data | G21: https://www.faa.gov/airports/engineering/aircraft_char_database/aircraft_data | H21: https://github.com/junzis/openap/blob/master/openap/data/aircraft/a21n.yml | I21: 209439 | J21: 146 | K21: Longitud total (FAA) | L21: FAA ACD octubre 2024: configuración de referencia, no máximo entre todas las variantes. AAC validated by Flight Standardization Board (FSB) report.
A22: A321 | B22: Airbus A321 | C22: OpenAP: parámetro wing.area (no BADA) | D22: https://github.com/junzis/openap/blob/master/openap/data/aircraft/a321.yml | E22: https://www.faa.gov/airports/engineering/aircraft_char_database/aircraft_data | F22: https://www.faa.gov/airports/engineering/aircraft_char_database/aircraft_data | G22: https://www.faa.gov/airports/engineering/aircraft_char_database/aircraft_data | H22: https://github.com/junzis/openap/blob/master/openap/data/aircraft/a321.yml | I22: 200621 | J22: 146 | K22: Longitud total (FAA) | L22: FAA ACD octubre 2024: configuración de referencia, no máximo entre todas las variantes. The final approach speed is 140 knot at a MALW of 166,449 lb and classifies the aircraft into the AAC C while approach speed is 142 knot at a MALW of 171,520 lb and classifies into the AAC D. AAC validated by Flight Standardization Board (FSB) report.
A23: B77W | B23: Boeing 777-300ER | C23: OpenAP: parámetro wing.area (no BADA) | D23: https://github.com/junzis/openap/blob/master/openap/data/aircraft/b77w.yml | E23: https://www.faa.gov/airports/engineering/aircraft_char_database/aircraft_data | F23: https://www.faa.gov/airports/engineering/aircraft_char_database/aircraft_data | G23: https://www.faa.gov/airports/engineering/aircraft_char_database/aircraft_data | H23: https://github.com/junzis/openap/blob/master/openap/data/aircraft/b77w.yml | I23: 775000 | J23: 242.3 | K23: Longitud total (FAA) | L23: FAA ACD octubre 2024: configuración de referencia, no máximo entre todas las variantes. AAC validated by Flight Standardization Board (FSB) report.
A24: BCS3 | C24: No disponible | E24: https://www.faa.gov/airports/engineering/aircraft_char_database/aircraft_data | F24: https://www.faa.gov/airports/engineering/aircraft_char_database/aircraft_data | G24: https://www.faa.gov/airports/engineering/aircraft_char_database/aircraft_data | I24: 156307 | J24: 127 | K24: Longitud total (FAA) | L24: FAA ACD octubre 2024: configuración de referencia, no máximo entre todas las variantes.
A25: B738 | B25: Boeing 737-800 | C25: OpenAP: parámetro wing.area (no BADA) | D25: https://github.com/junzis/openap/blob/master/openap/data/aircraft/b738.yml | E25: https://www.faa.gov/airports/engineering/aircraft_char_database/aircraft_data | F25: https://www.faa.gov/airports/engineering/aircraft_char_database/aircraft_data | G25: https://www.faa.gov/airports/engineering/aircraft_char_database/aircraft_data | H25: https://github.com/junzis/openap/blob/master/openap/data/aircraft/b738.yml | I25: 174200 | J25: 129.5 | K25: Longitud total (FAA) | L25: FAA ACD octubre 2024: configuración de referencia, no máximo entre todas las variantes. Depending on flaps configuration and MALW, AAC could be C. AAC validated by Flight Standardization Board (FSB) report.
A26: E195 | B26: Embraer E195 (LR) | C26: OpenAP: parámetro wing.area (no BADA) | D26: https://github.com/junzis/openap/blob/master/openap/data/aircraft/e195.yml | E26: https://www.faa.gov/airports/engineering/aircraft_char_database/aircraft_data | F26: https://www.faa.gov/airports/engineering/aircraft_char_database/aircraft_data | G26: https://www.faa.gov/airports/engineering/aircraft_char_database/aircraft_data | H26: https://github.com/junzis/openap/blob/master/openap/data/aircraft/e195.yml | I26: 115280 | J26: 126.8 | K26: Longitud total (FAA) | L26: FAA ACD octubre 2024: configuración de referencia, no máximo entre todas las variantes. AAC validated by Flight Standardization Board (FSB) report.
A27: B789 | B27: Boeing 787-9 | C27: OpenAP: parámetro wing.area (no BADA) | D27: https://github.com/junzis/openap/blob/master/openap/data/aircraft/b789.yml | E27: https://www.faa.gov/airports/engineering/aircraft_char_database/aircraft_data | F27: https://www.faa.gov/airports/engineering/aircraft_char_database/aircraft_data | G27: https://www.faa.gov/airports/engineering/aircraft_char_database/aircraft_data | H27: https://github.com/junzis/openap/blob/master/openap/data/aircraft/b789.yml | I27: 560000 | J27: 206.1 | K27: Longitud total (FAA) | L27: FAA ACD octubre 2024: configuración de referencia, no máximo entre todas las variantes. Depending on configurations and performance packages, AAC could be C. AAC validated by Flight Standardization Board (FSB) report.
A28: A343 | B28: Airbus A340-300 | C28: OpenAP: parámetro wing.area (no BADA) | D28: https://github.com/junzis/openap/blob/master/openap/data/aircraft/a343.yml | E28: https://www.faa.gov/airports/engineering/aircraft_char_database/aircraft_data | F28: https://www.faa.gov/airports/engineering/aircraft_char_database/aircraft_data | G28: https://www.faa.gov/airports/engineering/aircraft_char_database/aircraft_data | H28: https://github.com/junzis/openap/blob/master/openap/data/aircraft/a343.yml | I28: 609578 | J28: 209 | K28: Longitud total (FAA) | L28: FAA ACD octubre 2024: configuración de referencia, no máximo entre todas las variantes.
A29: A306 | C29: No disponible | E29: https://www.faa.gov/airports/engineering/aircraft_char_database/aircraft_data | F29: https://www.faa.gov/airports/engineering/aircraft_char_database/aircraft_data | G29: https://www.faa.gov/airports/engineering/aircraft_char_database/aircraft_data | I29: 363760 | J29: 177.4 | K29: Longitud total (FAA) | L29: FAA ACD octubre 2024: configuración de referencia, no máximo entre todas las variantes. AAC validated by Flight Standardization Board (FSB) report.
A30: B752 | B30: Boeing 757-200 | C30: OpenAP: parámetro wing.area (no BADA) | D30: https://github.com/junzis/openap/blob/master/openap/data/aircraft/b752.yml | E30: https://www.faa.gov/airports/engineering/aircraft_char_database/aircraft_data | F30: https://www.faa.gov/airports/engineering/aircraft_char_database/aircraft_data | G30: https://www.faa.gov/airports/engineering/aircraft_char_database/aircraft_data | H30: https://github.com/junzis/openap/blob/master/openap/data/aircraft/b752.yml | I30: 255500 | J30: 155.3 | K30: Longitud total (FAA) | L30: FAA ACD octubre 2024: configuración de referencia, no máximo entre todas las variantes.
A31: A359 | B31: Airbus A350-900 | C31: OpenAP: parámetro wing.area (no BADA) | D31: https://github.com/junzis/openap/blob/master/openap/data/aircraft/a359.yml | E31: https://www.faa.gov/airports/engineering/aircraft_char_database/aircraft_data | F31: https://www.faa.gov/airports/engineering/aircraft_char_database/aircraft_data | G31: https://www.faa.gov/airports/engineering/aircraft_char_database/aircraft_data | H31: https://github.com/junzis/openap/blob/master/openap/data/aircraft/a359.yml | I31: 617295 | J31: 218.54 | K31: Longitud total (FAA) | L31: FAA ACD octubre 2024: configuración de referencia, no máximo entre todas las variantes. AAC validated by Flight Standardization Board (FSB) report.
A32: B763 | B32: Boeing 767-300 | C32: OpenAP: parámetro wing.area (no BADA) | D32: https://github.com/junzis/openap/blob/master/openap/data/aircraft/b763.yml | E32: https://www.faa.gov/airports/engineering/aircraft_char_database/aircraft_data | F32: https://www.faa.gov/airports/engineering/aircraft_char_database/aircraft_data | G32: https://www.faa.gov/airports/engineering/aircraft_char_database/aircraft_data | H32: https://github.com/junzis/openap/blob/master/openap/data/aircraft/b763.yml | I32: 412000 | J32: 180.3 | K32: Longitud total (FAA) | L32: FAA ACD octubre 2024: configuración de referencia, no máximo entre todas las variantes.
A33: E55P | C33: No disponible | E33: https://www.faa.gov/airports/engineering/aircraft_char_database/aircraft_data | F33: https://www.faa.gov/airports/engineering/aircraft_char_database/aircraft_data | G33: https://www.faa.gov/airports/engineering/aircraft_char_database/aircraft_data | I33: 17968 | J33: 51.3 | K33: Longitud total (FAA) | L33: FAA ACD octubre 2024: configuración de referencia, no máximo entre todas las variantes. AAC validated by Flight Standardization Board (FSB) report.
A34: CL35 | C34: No disponible | E34: https://www.faa.gov/airports/engineering/aircraft_char_database/aircraft_data | F34: https://www.faa.gov/airports/engineering/aircraft_char_database/aircraft_data | G34: https://www.faa.gov/airports/engineering/aircraft_char_database/aircraft_data | I34: 40600 | J34: 68.6 | K34: Longitud total (FAA) | L34: FAA ACD octubre 2024: configuración de referencia, no máximo entre todas las variantes. AAC validated by Flight Standardization Board (FSB) report.
A35: C25B | B35: Citation CJ3 Gen3 | C35: Fabricante: Wing Area | D35: https://cessna.txtav.com/en/citation/cj3-gen2 | E35: https://www.faa.gov/airports/engineering/aircraft_char_database/aircraft_data | F35: https://www.faa.gov/airports/engineering/aircraft_char_database/aircraft_data | G35: https://www.faa.gov/airports/engineering/aircraft_char_database/aircraft_data | I35: 13870 | J35: 51.2 | K35: Longitud total (FAA) | L35: FAA ACD octubre 2024: configuración de referencia, no máximo entre todas las variantes. AAC validated by Flight Standardization Board (FSB) report.
A36: B78X | C36: No disponible | E36: https://www.faa.gov/airports/engineering/aircraft_char_database/aircraft_data | F36: https://www.faa.gov/airports/engineering/aircraft_char_database/aircraft_data | G36: https://www.faa.gov/airports/engineering/aircraft_char_database/aircraft_data | I36: 560000 | J36: 224.1 | K36: Longitud total (FAA) | L36: FAA ACD octubre 2024: configuración de referencia, no máximo entre todas las variantes. Approach speed estimated by Virginia Tech.
A37: B744 | B37: Boeing 747-400 | C37: OpenAP: parámetro wing.area (no BADA) | D37: https://github.com/junzis/openap/blob/master/openap/data/aircraft/b744.yml | E37: https://www.faa.gov/airports/engineering/aircraft_char_database/aircraft_data | F37: https://www.faa.gov/airports/engineering/aircraft_char_database/aircraft_data | G37: https://www.faa.gov/airports/engineering/aircraft_char_database/aircraft_data | H37: https://github.com/junzis/openap/blob/master/openap/data/aircraft/b744.yml | I37: 910000 | J37: 231.9 | K37: Longitud total (FAA) | L37: FAA ACD octubre 2024: configuración de referencia, no máximo entre todas las variantes. AAC validated by Flight Standardization Board (FSB) report.
A38: B38M | B38: Boeing 737 MAX 8 | C38: OpenAP: parámetro wing.area (no BADA) | D38: https://github.com/junzis/openap/blob/master/openap/data/aircraft/b38m.yml | E38: https://www.faa.gov/airports/engineering/aircraft_char_database/aircraft_data | F38: https://www.faa.gov/airports/engineering/aircraft_char_database/aircraft_data | G38: https://www.faa.gov/airports/engineering/aircraft_char_database/aircraft_data | H38: https://github.com/junzis/openap/blob/master/openap/data/aircraft/b38m.yml | I38: 181200 | J38: 129.7 | K38: Longitud total (FAA) | L38: FAA ACD octubre 2024: configuración de referencia, no máximo entre todas las variantes. Depending on flaps configuration and MALW, AAC could be C. AAC validated by Flight Standardization Board (FSB) report.
A39: AT72 | B39: ATR 72-200, opción MTOW | C39: Fabricante: superficie alar | D39: https://www.atr-aircraft.com/wp-content/uploads/2020/07/72-200.pdf | E39: https://www.atr-aircraft.com/wp-content/uploads/2020/07/72-200.pdf | F39: https://www.atr-aircraft.com/wp-content/uploads/2020/07/72-200.pdf | G39: https://www.faa.gov/airports/engineering/aircraft_char_database/aircraft_data | K39: Longitud general publicada por fabricante | L39: Ficha ATR pp. 1–2. MTOW básico 21500 kg, opción 22000 kg.
A40: B788 | B40: Boeing 787-8 | C40: OpenAP: parámetro wing.area (no BADA) | D40: https://github.com/junzis/openap/blob/master/openap/data/aircraft/b788.yml | E40: https://www.faa.gov/airports/engineering/aircraft_char_database/aircraft_data | F40: https://www.faa.gov/airports/engineering/aircraft_char_database/aircraft_data | G40: https://www.faa.gov/airports/engineering/aircraft_char_database/aircraft_data | H40: https://github.com/junzis/openap/blob/master/openap/data/aircraft/b788.yml | I40: 502500 | J40: 186.1 | K40: Longitud total (FAA) | L40: FAA ACD octubre 2024: configuración de referencia, no máximo entre todas las variantes. Depending on configurations and performance packages, AAC could be C. AAC validated by Flight Standardization Board (FSB) report.
A41: B772 | B41: Boeing 777-200/200ER | C41: OpenAP: parámetro wing.area (no BADA) | D41: https://github.com/junzis/openap/blob/master/openap/data/aircraft/b772.yml | E41: https://www.faa.gov/airports/engineering/aircraft_char_database/aircraft_data | F41: https://www.faa.gov/airports/engineering/aircraft_char_database/aircraft_data | G41: https://www.faa.gov/airports/engineering/aircraft_char_database/aircraft_data | H41: https://github.com/junzis/openap/blob/master/openap/data/aircraft/b772.yml | I41: 656000 | J41: 209.1 | K41: Longitud total (FAA) | L41: FAA ACD octubre 2024: configuración de referencia, no máximo entre todas las variantes. AAC validated by Flight Standardization Board (FSB) report.
C42: No disponible | K42: No disponible | L42: Fila vacía del CSV original; conservada.
A43: AT76 | B43: ATR 72-600, opción MTOW | C43: Fabricante: superficie alar | D43: https://www.atr-aircraft.com/wp-content/uploads/2020/07/Factsheets_-_ATR_72-600.pdf | E43: https://www.atr-aircraft.com/wp-content/uploads/2020/07/Factsheets_-_ATR_72-600.pdf | F43: https://www.atr-aircraft.com/wp-content/uploads/2020/07/Factsheets_-_ATR_72-600.pdf | G43: https://www.faa.gov/airports/engineering/aircraft_char_database/aircraft_data | K43: Longitud general publicada por fabricante | L43: MTOW básico 22800 kg; opción 23000 kg.
...

Sheet Guia
A1: Campo / criterio | B1: Interpretación
A2: Cobertura | B2: 243 filas conservadas en el orden del CSV; 225 con algún dato.
A3: Superficie alar pública | B3: 62 valores. Área de referencia publicada; no se calcula a partir de la envergadura. OpenAP y FAST son datos de modelos de investigación, no certificación ni BADA.
A4: MTOW | B4: 224 valores, en kg. Máximo al despegue de la configuración indicada por la fuente. No es necesariamente el mayor MTOW certificado entre todas las variantes del mismo código ni el de una matrícula concreta.
A5: Longitud del fuselaje | B5: 35 valores del campo fuselage.length de OpenAP. Se conserva el significado declarado por el modelo; no es una medición independiente del fuselaje.
A6: Longitud total / publicada | B6: 221 valores en m. FAA: Aircraft Full Length. Otras fichas: longitud general publicada. En helicópteros puede incluir rotores. No se intercambia con longitud estricta del fuselaje.
A7: Motores | B7: 225 valores. Número de motores principales de propulsión instalados; excluye APU y motores auxiliares. An-26: 2 principales y RU-19 auxiliar indicado en notas.
A8: BADA | B8: No se accedió a una base BADA licenciada. La columna se mantiene vacía; las fichas públicas de EUROCONTROL no se presentan como BADA. https://www.eurocontrol.int/model/bada
A9: Variantes | B9: El código ICAO puede abarcar distintas versiones. El modelo para MTOW está en Aeronaves; la variante de superficie está en Fuentes. No se garantiza que todos los campos correspondan a una misma subvariante.
A10: Designadores | B10: Se conserva el código del CSV, sin normalizar ni sustituir códigos dudosos. Los códigos sin ficha identificada se marcan Pendiente. ZZZZ no determina un modelo; la fila vacía se conserva.
A11: Conversiones | B11: 1 lb = 0.45359237 kg; 1 ft = 0.3048 m. Los datos FAA originales están en Fuentes; las conversiones son fórmulas. Visualización: kg enteros y m/m² con dos decimales.
A12: FAA | B12: Aircraft Characteristics Database, edición octubre 2024. Fuente base para coincidencias exactas de código. https://www.faa.gov/airports/engineering/aircraft_char_database
... A17: Fecha | B17: Fuentes consultadas el 13 de septiembre de 2026; la edición de una base puede ser anterior.
